Workbook

Sheet Teste 1
A1: Nome | B1: Nota
A2: ALAN DAVID SANTOS
A3: ALLAN YUKIO FURUHASHI MELO | B3: 10
A4: AMON CHALEGRE GOMES VANDERLEI
A5: ANDRÉ FELIPE FURRIEL OLIVEIRA | B5: 1
A6: ANIZIO SILVA CORREIA JÚNIOR | B6: 9
A7: ARTHUR BARBOSA PINHEIRO | B7: 1
A8: CARLOS EDUARDO MACHADO DOS SANTOS | B8: 6.5
A9: CARLOS EDUARDO ROCHA DE PAULA | B9: 10
A10: CRISTIANE MAGARINOS SAMPAIO | B10: 10
A11: DANIEL RODRIGUES SERQUEIRA | B11: 9.5
A12: DANIELA DE MENEZES MORAES | B12: 10
A13: DAVI BEZERRA LEAL GUIMARÃES | B13: 10
A14: DAVI PESTANA DE CAMPOS
A15: DULCE MARIA DE ALMEIDA COSTA | B15: 10
A16: EMILLY VITÓRIA LEITE REZENDE | B16: 10
A17: FELIPE BECKER FROHLICH | B17: 10
A18: FELIPE LERIA DE OLIVEIRA | B18: 10
A19: FELIPE LIMA DE SOUSA | B19: 10
A20: FELIPE RIBEIRO MENDONÇA | B20: 10
A21: GABRIEL COLATUSSO CASTRO DA CRUZ | B21: 10
A22: GABRIEL FALCÃO MARTINEZ | B22: 10
A23: GABRIEL KRAUSS DE SANTANA DIAS | B23: 10
A24: GABRIELA NAOMI ICHICAWA OGIDO | B24: 10
A25: GUILHERME OSÉIAS PEREIRA DA SILVA | B25: 0
A26: GUILHERME WILLEMEN PIMENTEL DE CASTRO
A27: HEITOR ALVES BRAZUNA | B27: 10
A28: HEITOR RAMOS PEREIRA | B28: 10
A29: Huann Vicente | B29: 9
A30: INGRID SILVA CARVALHO | B30: 10
A31: ITALO RENNAN DE ABREU SOUZA | B31: 10
A32: JONAS ARAUJO ALVES | B32: 10
A33: JOSÉ ARMANDO SILVA DUARTE | B33: 10
A34: JOSÉ RAFAEL FREITAS DE MELO | B34: 10
A35: JOSIETE MORAIS SANTOS SILVA
A36: JUAN MARTINS SANTOS | B36: 10
A37: JULIA QUIUQUI FONSECA | B37: 8
A38: KAUÃ MATTES REICHERT | B38: 10
A39: KAYKY LOPES TEIXEIRA MARTINS | B39: 10
A40: KENZO NAGAMINE | B40: 10
...

Sheet Teste 2
A1: Nome | B1: Nota
A2: ALAN DAVID SANTOS
A3: ALLAN YUKIO FURUHASHI MELO | B3: 10
A4: AMON CHALEGRE GOMES VANDERLEI
A5: ANDRÉ FELIPE FURRIEL OLIVEIRA | B5: 7.5
A6: ANIZIO SILVA CORREIA JÚNIOR | B6: 9
A7: ARTHUR BARBOSA PINHEIRO | B7: 9
A8: CARLOS EDUARDO MACHADO DOS SANTOS | B8: 9
A9: CARLOS EDUARDO ROCHA DE PAULA | B9: 10
A10: CRISTIANE MAGARINOS SAMPAIO | B10: 10
A11: DANIEL RODRIGUES SERQUEIRA | B11: 10
A12: DANIELA DE MENEZES MORAES | B12: 9.5
A13: DAVI BEZERRA LEAL GUIMARÃES | B13: 10
A14: DAVI PESTANA DE CAMPOS
A15: DULCE MARIA DE ALMEIDA COSTA | B15: 10
A16: EMILLY VITÓRIA LEITE REZENDE | B16: 10
A17: FELIPE BECKER FROHLICH | B17: 9
A18: FELIPE LERIA DE OLIVEIRA | B18: 10
A19: FELIPE LIMA DE SOUSA | B19: 7.5
A20: FELIPE RIBEIRO MENDONÇA | B20: 9
A21: GABRIEL COLATUSSO CASTRO DA CRUZ | B21: 10
A22: GABRIEL FALCÃO MARTINEZ | B22: 10
A23: GABRIEL KRAUSS DE SANTANA DIAS | B23: 10
A24: GABRIELA NAOMI ICHICAWA OGIDO | B24: 9
A25: GUILHERME OSÉIAS PEREIRA DA SILVA | B25: 10
A26: GUILHERME WILLEMEN PIMENTEL DE CASTRO
A27: HEITOR ALVES BRAZUNA | B27: 10
A28: HEITOR RAMOS PEREIRA | B28: 10
A29: Huann Vicente | B29: 9
A30: INGRID SILVA CARVALHO | B30: 10
A31: ITALO RENNAN DE ABREU SOUZA | B31: 10
A32: JONAS ARAUJO ALVES | B32: 8
A33: JOSÉ ARMANDO SILVA DUARTE | B33: 9.5
A34: JOSÉ RAFAEL FREITAS DE MELO | B34: 9
A35: JOSIETE MORAIS SANTOS SILVA
A36: JUAN MARTINS SANTOS | B36: 10
A37: JULIA QUIUQUI FONSECA | B37: 10
A38: KAUÃ MATTES REICHERT | B38: 10
A39: KAYKY LOPES TEIXEIRA MARTINS | B39: 10
A40: KENZO NAGAMINE | B40: 10
...

Sheet Lista 1
A1: Nome | B1: Entrega | C1: Questão (Renato) | D1: Nota (Renato) | E1: Questão (Diego) | F1: Nota (Diego) | G1: Total
A2: ALAN DAVID SANTOS | B2: 0 | E2: =IF(B2=0,0,) -> 0 | F2: =IF(B2=0,0,) -> 0 | G2: =SUM(D2,F2) -> 0
A3: ALLAN YUKIO FURUHASHI MELO | B3: 1 | C3: Quatro | D3: 5 | E3: Oito | F3: 5 | G3: =SUM(D3,F3) -> 10
A4: AMON CHALEGRE GOMES VANDERLEI | B4: 0 | E4: =IF(B4=0,0,) -> 0 | F4: =IF(B4=0,0,) -> 0 | G4: =SUM(D4,F4) -> 0
A5: ANDRÉ FELIPE FURRIEL OLIVEIRA | B5: 1 | C5: Cinco | D5: 5 | E5: Oito | F5: 4.8 | G5: =SUM(D5,F5) -> 9.8
A6: ANIZIO SILVA CORREIA JÚNIOR | B6: 1 | C6: Um | D6: 5 | E6: Oito | F6: 5 | G6: =SUM(D6,F6) -> 10
A7: ARTHUR BARBOSA PINHEIRO | B7: 1 | C7: Três | D7: 5 | E7: Oito | F7: 5 | G7: =SUM(D7,F7) -> 10
A8: CARLOS EDUARDO MACHADO DOS SANTOS | B8: 1 | C8: Um | D8: 5 | E8: Oito | F8: 2 | G8: =SUM(D8,F8) -> 7
A9: CARLOS EDUARDO ROCHA DE PAULA | B9: 1 | C9: Dois | D9: 5 | E9: Oito | F9: 4.8 | G9: =SUM(D9,F9) -> 9.8
A10: CRISTIANE MAGARINOS SAMPAIO | B10: 1 | C10: Três | D10: 3 | E10: Oito | F10: 4.8 | G10: =SUM(D10,F10) -> 7.8
A11: DANIEL RODRIGUES SERQUEIRA | B11: 1 | C11: Cinco | D11: 5 | E11: Oito | F11: 5 | G11: =SUM(D11,F11) -> 10
A12: DANIELA DE MENEZES MORAES | B12: 1 | C12: Quatro | D12: 5 | E12: Oito | F12: 5 | G12: =SUM(D12,F12) -> 10
A13: DAVI BEZERRA LEAL GUIMARÃES | B13: 1 | C13: Cinco | D13: 5 | E13: Oito | F13: 5 | G13: =SUM(D13,F13) -> 10
A14: DAVI PESTANA DE CAMPOS | B14: 0 | E14: =IF(B14=0,0,) -> 0 | F14: =IF(B14=0,0,) -> 0 | G14: =SUM(D14,F14) -> 0
A15: DULCE MARIA DE ALMEIDA COSTA | B15: 1 | C15: Três | D15: 5 | E15: Oito | F15: 5 | G15: =SUM(D15,F15) -> 10
A16: EMILLY VITÓRIA LEITE REZENDE | B16: 1 | C16: Um | D16: 5 | E16: Oito | F16: 4.8 | G16: =SUM(D16,F16) -> 9.8
A17: FELIPE BECKER FROHLICH | B17: 1 | C17: Quatro | D17: 5 | E17: Oito | F17: 5 | G17: =SUM(D17,F17) -> 10
A18: FELIPE LERIA DE OLIVEIRA | B18: 1 | C18: Três | D18: 3 | E18: Oito | F18: 5 | G18: =SUM(D18,F18) -> 8
A19: FELIPE LIMA DE SOUSA | B19: 1 | C19: Dois | D19: 4 | E19: Oito | F19: 4.5 | G19: =SUM(D19,F19) -> 8.5
A20: FELIPE RIBEIRO MENDONÇA | B20: 1 | C20: Quatro | D20: 5 | E20: Oito | F20: 5 | G20: =SUM(D20,F20) -> 10
A21: GABRIEL COLATUSSO CASTRO DA CRUZ | B21: 1 | C21: Dois | D21: 5 | E21: Oito | F21: 2 | G21: =SUM(D21,F21) -> 7
A22: GABRIEL FALCÃO MARTINEZ | B22: 1 | C22: Cinco | D22: 5 | E22: Oito | F22: 5 | G22: =SUM(D22,F22) -> 10
A23: GABRIEL KRAUSS DE SANTANA DIAS | B23: 1 | C23: Quatro | D23: 5 | E23: Oito | F23: 4.8 | G23: =SUM(D23,F23) -> 9.8
A24: GABRIELA NAOMI ICHICAWA OGIDO | B24: 1 | C24: Um | D24: 5 | E24: Oito | F24: 4.8 | G24: =SUM(D24,F24) -> 9.8
A25: GUILHERME OSÉIAS PEREIRA DA SILVA | B25: 1 | C25: Cinco | D25: 4 | E25: Oito | F25: 5 | G25: =SUM(D25,F25) -> 9
A26: GUILHERME WILLEMEN PIMENTEL DE CASTRO | B26: 0 | E26: =IF(B26=0,0,) -> 0 | F26: =IF(B26=0,0,) -> 0 | G26: =SUM(D26,F26) -> 0
A27: HEITOR ALVES BRAZUNA | B27: 1 | C27: Dois | D27: 5 | E27: Oito | F27: 4.8 | G27: =SUM(D27,F27) -> 9.8
A28: HEITOR RAMOS PEREIRA | B28: 1 | C28: Cinco | D28: 5 | E28: Oito | F28: 5 | G28: =SUM(D28,F28) -> 10
A29: Huann Vicente | B29: 1 | C29: Quatro | D29: 5 | E29: Oito | F29: 5 | G29: =SUM(D29,F29) -> 10
A30: INGRID SILVA CARVALHO | B30: 1 | C30: Cinco | D30: 5 | E30: Oito | F30: 4.8 | G30: =SUM(D30,F30) -> 9.8
A31: ITALO RENNAN DE ABREU SOUZA | B31: 1 | C31: Um | D31: 5 | E31: Oito | F31: 5 | G31: =SUM(D31,F31) -> 10
A32: JONAS ARAUJO ALVES | B32: 1 | C32: Dois | D32: 5 | E32: Oito | F32: 4.5 | G32: =SUM(D32,F32) -> 9.5
A33: JOSÉ ARMANDO SILVA DUARTE | B33: 1 | C33: Cinco | D33: 5 | E33: Oito | F33: 4.8 | G33: =SUM(D33,F33) -> 9.8
A34: JOSÉ RAFAEL FREITAS DE MELO | B34: 1 | C34: Três | D34: 5 | E34: Oito | F34: 4.5 | G34: =SUM(D34,F34) -> 9.5
A35: JOSIETE MORAIS SANTOS SILVA | B35: 0 | E35: =IF(B35=0,0,) -> 0 | F35: =IF(B35=0,0,) -> 0 | G35: =SUM(D35,F35) -> 0
A36: JUAN MARTINS SANTOS | B36: 1 | C36: Um | D36: 5 | E36: Oito | F36: 5 | G36: =SUM(D36,F36) -> 10
A37: JULIA QUIUQUI FONSECA | B37: 1 | C37: Dois | D37: 5 | E37: Oito | F37: 5 | G37: =SUM(D37,F37) -> 10
A38: KAUÃ MATTES REICHERT | B38: 1 | C38: Cinco | D38: 5 | E38: Oito | F38: 5 | G38: =SUM(D38,F38) -> 10
A39: KAYKY LOPES TEIXEIRA MARTINS | B39: 1 | C39: Quatro | D39: 5 | E39: Oito | F39: 5 | G39: =SUM(D39,F39) -> 10
A40: KENZO NAGAMINE | B40: 1 | C40: Cinco | D40: 5 | E40: Oito | F40: 5 | G40: =SUM(D40,F40) -> 10
...

Sheet Lista 2
A1: Nome | B1: Entrega | C1: Questão (Renato) | D1: Nota (Renato) | E1: Questão (Diego) | F1: Nota (Diego) | G1: Questão (Joel) | H1: Nota (Joel) | I1: Total
A2: ALAN DAVID SANTOS | B2: 0 | I2: =SUM(D2,F2,H2) -> 0
A3: ALLAN YUKIO FURUHASHI MELO | B3: 1 | I3: =SUM(D3,F3,H3) -> 0
A4: AMON CHALEGRE GOMES VANDERLEI | B4: 0 | I4: =SUM(D4,F4,H4) -> 0
A5: ANDRÉ FELIPE FURRIEL OLIVEIRA | B5: 0 | I5: =SUM(D5,F5,H5) -> 0
A6: ANIZIO SILVA CORREIA JÚNIOR | B6: 1 | I6: =SUM(D6,F6,H6) -> 0
A7: ARTHUR BARBOSA PINHEIRO | B7: 1 | I7: =SUM(D7,F7,H7) -> 0
A8: CARLOS EDUARDO MACHADO DOS SANTOS | B8: 1 | I8: =SUM(D8,F8,H8) -> 0
A9: CARLOS EDUARDO ROCHA DE PAULA | B9: 1 | I9: =SUM(D9,F9,H9) -> 0
A10: CRISTIANE MAGARINOS SAMPAIO | B10: 1 | I10: =SUM(D10,F10,H10) -> 0
A11: DANIEL RODRIGUES SERQUEIRA | B11: 1 | I11: =SUM(D11,F11,H11) -> 0
A12: DANIELA DE MENEZES MORAES | B12: 1 | I12: =SUM(D12,F12,H12) -> 0
A13: DAVI BEZERRA LEAL GUIMARÃES | B13: 1 | I13: =SUM(D13,F13,H13) -> 0
... A79: YASMIN DE BARROS DA SILVA | B79: 1 | I79: =SUM(D79,F79,H79) -> 0

Sheet Prova 1
A1: Nome | B1: Total
A2: ALAN DAVID SANTOS | B2: 0
A3: ALLAN YUKIO FURUHASHI MELO | B3: 21
A4: AMON CHALEGRE GOMES VANDERLEI | B4: 0
A5: ANDRÉ FELIPE FURRIEL OLIVEIRA | B5: 21
A6: ANIZIO SILVA CORREIA JÚNIOR | B6: 19
A7: ARTHUR BARBOSA PINHEIRO | B7: 22
A8: CARLOS EDUARDO MACHADO DOS SANTOS | B8: 35
A9: CARLOS EDUARDO ROCHA DE PAULA | B9: 20
A10: CRISTIANE MAGARINOS SAMPAIO | B10: 45
A11: DANIEL RODRIGUES SERQUEIRA | B11: 75
A12: DANIELA DE MENEZES MORAES | B12: 20
A13: DAVI BEZERRA LEAL GUIMARÃES | B13: 67
... A79: YASMIN DE BARROS DA SILVA | B79: 42
A80: MEDIA | B80: =AVERAGE(B2:B79) -> 38.038462
A81: DESVIO PADRÃO | B81: =STDEV(B2:B79) -> 26.156096

Sheet Média
A1: Nome | B1: Teste 1 | C1: Teste 2 | D1: Média Testes | E1: Entrega Lista 1 | F1: Entrega Lista 2 | G1: Média Entrega Normalizado | H1: Lista 1 | I1: Lista 2 | J1: Média Listas | K1: Prova 1 | L1: AV1
A2: ALAN DAVID SANTOS | B2: ='Teste 1'!B2 -> 0 | C2: ='Teste 2'!B2 -> 0 | D2: =SUM(B2:C2)/2 -> 0 | E2: ='Lista 1'!B2 -> 0 | F2: ='Lista 2'!B2 -> 0 | G2: =SUM(E2:F2)*5 -> 0 | H2: ='Lista 1'!G2 -> 0 | I2: 0 | J2: =SUM(H2:I2)/2 -> 0 | K2: ='Prova 1'!B2/10 -> 0 | L2: 0
A3: ALLAN YUKIO FURUHASHI MELO | B3: ='Teste 1'!B3 -> 10 | C3: ='Teste 2'!B3 -> 10 | D3: =SUM(B3:C3)/2 -> 10 | E3: ='Lista 1'!B3 -> 1 | F3: ='Lista 2'!B3 -> 1 | G3: =SUM(E3:F3)*5 -> 10 | H3: ='Lista 1'!G3 -> 10 | I3: =10 -> 10 | J3: =SUM(H3:I3)/2 -> 10 | K3: ='Prova 1'!B3/10 -> 2.1 | L3: =_xlfn.FLOOR.MATH(10*((SUM(D3*0.2,G3*0.05,J3*0.05,K3)*(6/5))*(20/43) + (138/43)))/10 -> 6
A4: AMON CHALEGRE GOMES VANDERLEI | B4: ='Teste 1'!B4 -> 0 | C4: ='Teste 2'!B4 -> 0 | D4: =SUM(B4:C4)/2 -> 0 | E4: ='Lista 1'!B4 -> 0 | F4: ='Lista 2'!B4 -> 0 | G4: =SUM(E4:F4)*5 -> 0 | H4: ='Lista 1'!G4 -> 0 | I4: 0 | J4: =SUM(H4:I4)/2 -> 0 | K4: ='Prova 1'!B4/10 -> 0 | L4: 0
A5: ANDRÉ FELIPE FURRIEL OLIVEIRA | B5: ='Teste 1'!B5 -> 1 | C5: ='Teste 2'!B5 -> 7.5 | D5: =SUM(B5:C5)/2 -> 4.25 | E5: ='Lista 1'!B5 -> 1 | F5: ='Lista 2'!B5 -> 0 | G5: =SUM(E5:F5)*5 -> 5 | H5: ='Lista 1'!G5 -> 9.8 | I5: 0 | J5: =SUM(H5:I5)/2 -> 4.9 | K5: ='Prova 1'!B5/10 -> 2.1 | L5: =_xlfn.FLOOR.MATH(10*((SUM(D5*0.2,G5*0.05,J5*0.05,K5)*(6/5))*(20/43) + (138/43)))/10 -> 5.1
A6: ANIZIO SILVA CORREIA JÚNIOR | B6: ='Teste 1'!B6 -> 9 | C6: ='Teste 2'!B6 -> 9 | D6: =SUM(B6:C6)/2 -> 9 | E6: ='Lista 1'!B6 -> 1 | F6: ='Lista 2'!B6 -> 1 | G6: =SUM(E6:F6)*5 -> 10 | H6: ='Lista 1'!G6 -> 10 | I6: =10 -> 10 | J6: =SUM(H6:I6)/2 -> 10 | K6: ='Prova 1'!B6/10 -> 1.9 | L6: =_xlfn.FLOOR.MATH(10*((SUM(D6*0.2,G6*0.05,J6*0.05,K6)*(6/5))*(20/43) + (138/43)))/10 -> 5.8
A7: ARTHUR BARBOSA PINHEIRO | B7: ='Teste 1'!B7 -> 1 | C7: ='Teste 2'!B7 -> 9 | D7: =SUM(B7:C7)/2 -> 5 | E7: ='Lista 1'!B7 -> 1 | F7: ='Lista 2'!B7 -> 1 | G7: =SUM(E7:F7)*5 -> 10 | H7: ='Lista 1'!G7 -> 10 | I7: =10 -> 10 | J7: =SUM(H7:I7)/2 -> 10 | K7: ='Prova 1'!B7/10 -> 2.2 | L7: =_xlfn.FLOOR.MATH(10*((SUM(D7*0.2,G7*0.05,J7*0.05,K7)*(6/5))*(20/43) + (138/43)))/10 -> 5.5
A8: CARLOS EDUARDO MACHADO DOS SANTOS | B8: ='Teste 1'!B8 -> 6.5 | C8: ='Teste 2'!B8 -> 9 | D8: =SUM(B8:C8)/2 -> 7.75 | E8: ='Lista 1'!B8 -> 1 | F8: ='Lista 2'!B8 -> 1 | G8: =SUM(E8:F8)*5 -> 10 | H8: ='Lista 1'!G8 -> 7 | I8: =10 -> 10 | J8: =SUM(H8:I8)/2 -> 8.5 | K8: ='Prova 1'!B8/10 -> 3.5 | L8: =_xlfn.FLOOR.MATH(10*((SUM(D8*0.2,G8*0.05,J8*0.05,K8)*(6/5))*(20/43) + (138/43)))/10 -> 6.5
A9: CARLOS EDUARDO ROCHA DE PAULA | B9: ='Teste 1'!B9 -> 10 | C9: ='Teste 2'!B9 -> 10 | D9: =SUM(B9:C9)/2 -> 10 | E9: ='Lista 1'!B9 -> 1 | F9: ='Lista 2'!B9 -> 1 | G9: =SUM(E9:F9)*5 -> 10 | H9: ='Lista 1'!G9 -> 9.8 | I9: =10 -> 10 | J9: =SUM(H9:I9)/2 -> 9.9 | K9: ='Prova 1'!B9/10 -> 2 | L9: 6
A10: CRISTIANE MAGARINOS SAMPAIO | B10: ='Teste 1'!B10 -> 10 | C10: ='Teste 2'!B10 -> 10 | D10: =SUM(B10:C10)/2 -> 10 | E10: ='Lista 1'!B10 -> 1 | F10: ='Lista 2'!B10 -> 1 | G10: =SUM(E10:F10)*5 -> 10 | H10: ='Lista 1'!G10 -> 7.8 | I10: =10 -> 10 | J10: =SUM(H10:I10)/2 -> 8.9 | K10: ='Prova 1'!B10/10 -> 4.5 | L10: =_xlfn.FLOOR.MATH(10*((SUM(D10*0.2,G10*0.05,J10*0.05,K10)*(6/5))*(20/43) + (138/43)))/10 -> 7.3
A11: DANIEL RODRIGUES SERQUEIRA | B11: ='Teste 1'!B11 -> 9.5 | C11: ='Teste 2'!B11 -> 10 | D11: =SUM(B11:C11)/2 -> 9.75 | E11: ='Lista 1'!B11 -> 1 | F11: ='Lista 2'!B11 -> 1 | G11: =SUM(E11:F11)*5 -> 10 | H11: ='Lista 1'!G11 -> 10 | I11: =10 -> 10 | J11: =SUM(H11:I11)/2 -> 10 | K11: ='Prova 1'!B11/10 -> 7.5 | L11: =_xlfn.FLOOR.MATH(10*((SUM(D11*0.2,G11*0.05,J11*0.05,K11)*(6/5))*(20/43) + (138/43)))/10 -> 9
A12: DANIELA DE MENEZES MORAES | B12: ='Teste 1'!B12 -> 10 | C12: ='Teste 2'!B12 -> 9.5 | D12: =SUM(B12:C12)/2 -> 9.75 | E12: ='Lista 1'!B12 -> 1 | F12: ='Lista 2'!B12 -> 1 | G12: =SUM(E12:F12)*5 -> 10 | H12: ='Lista 1'!G12 -> 10 | I12: =10 -> 10 | J12: =SUM(H12:I12)/2 -> 10 | K12: ='Prova 1'!B12/10 -> 2 | L12: 6
A13: DAVI BEZERRA LEAL GUIMARÃES | B13: ='Teste 1'!B13 -> 10 | C13: ='Teste 2'!B13 -> 10 | D13: =SUM(B13:C13)/2 -> 10 | E13: ='Lista 1'!B13 -> 1 | F13: ='Lista 2'!B13 -> 1 | G13: =SUM(E13:F13)*5 -> 10 | H13: ='Lista 1'!G13 -> 10 | I13: =10 -> 10 | J13: =SUM(H13:I13)/2 -> 10 | K13: ='Prova 1'!B13/10 -> 6.7 | L13: =_xlfn.FLOOR.MATH(10*((SUM(D13*0.2,G13*0.05,J13*0.05,K13)*(6/5))*(20/43) + (138/43)))/10 -> 8.6
A14: DAVI PESTANA DE CAMPOS | B14: ='Teste 1'!B14 -> 0 | C14: ='Teste 2'!B14 -> 0 | D14: =SUM(B14:C14)/2 -> 0 | E14: ='Lista 1'!B14 -> 0 | F14: ='Lista 2'!B14 -> 0 | G14: =SUM(E14:F14)*5 -> 0 | H14: ='Lista 1'!G14 -> 0 | I14: 0 | J14: =SUM(H14:I14)/2 -> 0 | K14: ='Prova 1'!B14/10 -> 0 | L14: 0
A15: DULCE MARIA DE ALMEIDA COSTA | B15: ='Teste 1'!B15 -> 10 | C15: ='Teste 2'!B15 -> 10 | D15: =SUM(B15:C15)/2 -> 10 | E15: ='Lista 1'!B15 -> 1 | F15: ='Lista 2'!B15 -> 1 | G15: =SUM(E15:F15)*5 -> 10 | H15: ='Lista 1'!G15 -> 10 | I15: =10 -> 10 | J15: =SUM(H15:I15)/2 -> 10 | K15: ='Prova 1'!B15/10 -> 3.7 | L15: =_xlfn.FLOOR.MATH(10*((SUM(D15*0.2,G15*0.05,J15*0.05,K15)*(6/5))*(20/43) + (138/43)))/10 -> 6.9
A16: EMILLY VITÓRIA LEITE REZENDE | B16: ='Teste 1'!B16 -> 10 | C16: ='Teste 2'!B16 -> 10 | D16: =SUM(B16:C16)/2 -> 10 | E16: ='Lista 1'!B16 -> 1 | F16: ='Lista 2'!B16 -> 1 | G16: =SUM(E16:F16)*5 -> 10 | H16: ='Lista 1'!G16 -> 9.8 | I16: =10 -> 10 | J16: =SUM(H16:I16)/2 -> 9.9 | K16: ='Prova 1'!B16/10 -> 1.8 | L16: =_xlfn.FLOOR.MATH(10*((SUM(D16*0.2,G16*0.05,J16*0.05,K16)*(6/5))*(20/43) + (138/43)))/10 -> 5.8
A17: FELIPE BECKER FROHLICH | B17: ='Teste 1'!B17 -> 10 | C17: ='Teste 2'!B17 -> 9 | D17: =SUM(B17:C17)/2 -> 9.5 | E17: ='Lista 1'!B17 -> 1 | F17: ='Lista 2'!B17 -> 1 | G17: =SUM(E17:F17)*5 -> 10 | H17: ='Lista 1'!G17 -> 10 | I17: =10 -> 10 | J17: =SUM(H17:I17)/2 -> 10 | K17: ='Prova 1'!B17/10 -> 9.1 | L17: 10
A18: FELIPE LERIA DE OLIVEIRA | B18: ='Teste 1'!B18 -> 10 | C18: ='Teste 2'!B18 -> 10 | D18: =SUM(B18:C18)/2 -> 10 | E18: ='Lista 1'!B18 -> 1 | F18: ='Lista 2'!B18 -> 1 | G18: =SUM(E18:F18)*5 -> 10 | H18: ='Lista 1'!G18 -> 8 | I18: =10 -> 10 | J18: =SUM(H18:I18)/2 -> 9 | K18: ='Prova 1'!B18/10 -> 1.6 | L18: =_xlfn.FLOOR.MATH(10*((SUM(D18*0.2,G18*0.05,J18*0.05,K18)*(6/5))*(20/43) + (138/43)))/10 -> 5.7
A19: FELIPE LIMA DE SOUSA | B19: ='Teste 1'!B19 -> 10 | C19: ='Teste 2'!B19 -> 7.5 | D19: =SUM(B19:C19)/2 -> 8.75 | E19: ='Lista 1'!B19 -> 1 | F19: ='Lista 2'!B19 -> 1 | G19: =SUM(E19:F19)*5 -> 10 | H19: ='Lista 1'!G19 -> 8.5 | I19: =10 -> 10 | J19: =SUM(H19:I19)/2 -> 9.25 | K19: ='Prova 1'!B19/10 -> 1.5 | L19: =_xlfn.FLOOR.MATH(10*((SUM(D19*0.2,G19*0.05,J19*0.05,K19)*(6/5))*(20/43) + (138/43)))/10 -> 5.5
A20: FELIPE RIBEIRO MENDONÇA | B20: ='Teste 1'!B20 -> 10 | C20: ='Teste 2'!B20 -> 9 | D20: =SUM(B20:C20)/2 -> 9.5 | E20: ='Lista 1'!B20 -> 1 | F20: ='Lista 2'!B20 -> 1 | G20: =SUM(E20:F20)*5 -> 10 | H20: ='Lista 1'!G20 -> 10 | I20: =10 -> 10 | J20: =SUM(H20:I20)/2 -> 10 | K20: ='Prova 1'!B20/10 -> 3.1 | L20: =_xlfn.FLOOR.MATH(10*((SUM(D20*0.2,G20*0.05,J20*0.05,K20)*(6/5))*(20/43) + (138/43)))/10 -> 6.5
A21: GABRIEL COLATUSSO CASTRO DA CRUZ | B21: ='Teste 1'!B21 -> 10 | C21: ='Teste 2'!B21 -> 10 | D21: =SUM(B21:C21)/2 -> 10 | E21: ='Lista 1'!B21 -> 1 | F21: ='Lista 2'!B21 -> 1 | G21: =SUM(E21:F21)*5 -> 10 | H21: ='Lista 1'!G21 -> 7 | I21: =10 -> 10 | J21: =SUM(H21:I21)/2 -> 8.5 | K21: ='Prova 1'!B21/10 -> 2.7 | L21: =_xlfn.FLOOR.MATH(10*((SUM(D21*0.2,G21*0.05,J21*0.05,K21)*(6/5))*(20/43) + (138/43)))/10 -> 6.3
A22: GABRIEL FALCÃO MARTINEZ | B22: ='Teste 1'!B22 -> 10 | C22: ='Teste 2'!B22 -> 10 | D22: =SUM(B22:C22)/2 -> 10 | E22: ='Lista 1'!B22 -> 1 | F22: ='Lista 2'!B22 -> 1 | G22: =SUM(E22:F22)*5 -> 10 | H22: ='Lista 1'!G22 -> 10 | I22: =10 -> 10 | J22: =SUM(H22:I22)/2 -> 10 | K22: ='Prova 1'!B22/10 -> 9.1 | L22: 10
A23: GABRIEL KRAUSS DE SANTANA DIAS | B23: ='Teste 1'!B23 -> 10 | C23: ='Teste 2'!B23 -> 10 | D23: =SUM(B23:C23)/2 -> 10 | E23: ='Lista 1'!B23 -> 1 | F23: ='Lista 2'!B23 -> 1 | G23: =SUM(E23:F23)*5 -> 10 | H23: ='Lista 1'!G23 -> 9.8 | I23: =10 -> 10 | J23: =SUM(H23:I23)/2 -> 9.9 | K23: ='Prova 1'!B23/10 -> 4.4 | L23: =_xlfn.FLOOR.MATH(10*((SUM(D23*0.2,G23*0.05,J23*0.05,K23)*(6/5))*(20/43) + (138/43)))/10 -> 7.3
A24: GABRIELA NAOMI ICHICAWA OGIDO | B24: ='Teste 1'!B24 -> 10 | C24: ='Teste 2'!B24 -> 9 | D24: =SUM(B24:C24)/2 -> 9.5 | E24: ='Lista 1'!B24 -> 1 | F24: ='Lista 2'!B24 -> 1 | G24: =SUM(E24:F24)*5 -> 10 | H24: ='Lista 1'!G24 -> 9.8 | I24: =10 -> 10 | J24: =SUM(H24:I24)/2 -> 9.9 | K24: ='Prova 1'!B24/10 -> 3.7 | L24: =_xlfn.FLOOR.MATH(10*((SUM(D24*0.2,G24*0.05,J24*0.05,K24)*(6/5))*(20/43) + (138/43)))/10 -> 6.8
A25: GUILHERME OSÉIAS PEREIRA DA SILVA | B25: ='Teste 1'!B25 -> 0 | C25: ='Teste 2'!B25 -> 10 | D25: =SUM(B25:C25)/2 -> 5 | E25: ='Lista 1'!B25 -> 1 | F25: ='Lista 2'!B25 -> 1 | G25: =SUM(E25:F25)*5 -> 10 | H25: ='Lista 1'!G25 -> 9 | I25: =10 -> 10 | J25: =SUM(H25:I25)/2 -> 9.5 | K25: ='Prova 1'!B25/10 -> 2.5 | L25: =_xlfn.FLOOR.MATH(10*((SUM(D25*0.2,G25*0.05,J25*0.05,K25)*(6/5))*(20/43) + (138/43)))/10 -> 5.7
A26: GUILHERME WILLEMEN PIMENTEL DE CASTRO | B26: ='Teste 1'!B26 -> 0 | C26: ='Teste 2'!B26 -> 0 | D26: =SUM(B26:C26)/2 -> 0 | E26: ='Lista 1'!B26 -> 0 | F26: ='Lista 2'!B26 -> 0 | G26: =SUM(E26:F26)*5 -> 0 | H26: ='Lista 1'!G26 -> 0 | I26: 0 | J26: =SUM(H26:I26)/2 -> 0 | K26: ='Prova 1'!B26/10 -> 0 | L26: 0
A27: HEITOR ALVES BRAZUNA | B27: ='Teste 1'!B27 -> 10 | C27: ='Teste 2'!B27 -> 10 | D27: =SUM(B27:C27)/2 -> 10 | E27: ='Lista 1'!B27 -> 1 | F27: ='Lista 2'!B27 -> 1 | G27: =SUM(E27:F27)*5 -> 10 | H27: ='Lista 1'!G27 -> 9.8 | I27: =10 -> 10 | J27: =SUM(H27:I27)/2 -> 9.9 | K27: 8.3 | L27: =_xlfn.FLOOR.MATH(10*((SUM(D27*0.2,G27*0.05,J27*0.05,K27)*(6/5))*(20/43) + (138/43)))/10 -> 9.5 | M27: OBS: +0.7 na AV2 (se nota(AV2) > 9.7, nota final = 10)
A28: HEITOR RAMOS PEREIRA | B28: ='Teste 1'!B28 -> 10 | C28: ='Teste 2'!B28 -> 10 | D28: =SUM(B28:C28)/2 -> 10 | E28: ='Lista 1'!B28 -> 1 | F28: ='Lista 2'!B28 -> 1 | G28: =SUM(E28:F28)*5 -> 10 | H28: ='Lista 1'!G28 -> 10 | I28: =10 -> 10 | J28: =SUM(H28:I28)/2 -> 10 | K28: ='Prova 1'!B28/10 -> 9.3 | L28: =_xlfn.FLOOR.MATH(10*((SUM(D28*0.2,G28*0.05,J28*0.05,K28)*(6/5))*(20/43) + (138/43)))/10 -> 10
A29: HUANN VICENTE | B29: ='Teste 1'!B29 -> 9 | C29: ='Teste 2'!B29 -> 9 | D29: =SUM(B29:C29)/2 -> 9 | E29: ='Lista 1'!B29 -> 1 | F29: ='Lista 2'!B29 -> 1 | G29: =SUM(E29:F29)*5 -> 10 | H29: ='Lista 1'!G29 -> 10 | I29: =10 -> 10 | J29: =SUM(H29:I29)/2 -> 10 | K29: ='Prova 1'!B29/10 -> 1.5 | L29: =_xlfn.FLOOR.MATH(10*((SUM(D29*0.2,G29*0.05,J29*0.05,K29)*(6/5))*(20/43) + (138/43)))/10 -> 5.6
A30: INGRID SILVA CARVALHO | B30: ='Teste 1'!B30 -> 10 | C30: ='Teste 2'!B30 -> 10 | D30: =SUM(B30:C30)/2 -> 10 | E30: ='Lista 1'!B30 -> 1 | F30: ='Lista 2'!B30 -> 1 | G30: =SUM(E30:F30)*5 -> 10 | H30: ='Lista 1'!G30 -> 9.8 | I30: =10 -> 10 | J30: =SUM(H30:I30)/2 -> 9.9 | K30: ='Prova 1'!B30/10 -> 4.3 | L30: =_xlfn.FLOOR.MATH(10*((SUM(D30*0.2,G30*0.05,J30*0.05,K30)*(6/5))*(20/43) + (138/43)))/10 -> 7.2
A31: ITALO RENNAN DE ABREU SOUZA | B31: ='Teste 1'!B31 -> 10 | C31: ='Teste 2'!B31 -> 10 | D31: =SUM(B31:C31)/2 -> 10 | E31: ='Lista 1'!B31 -> 1 | F31: ='Lista 2'!B31 -> 1 | G31: =SUM(E31:F31)*5 -> 10 | H31: ='Lista 1'!G31 -> 10 | I31: =10 -> 10 | J31: =SUM(H31:I31)/2 -> 10 | K31: 5.5 | L31: =_xlfn.FLOOR.MATH(10*((SUM(D31*0.2,G31*0.05,J31*0.05,K31)*(6/5))*(20/43) + (138/43)))/10 -> 7.9
A32: JONAS ARAUJO ALVES | B32: ='Teste 1'!B32 -> 10 | C32: ='Teste 2'!B32 -> 8 | D32: =SUM(B32:C32)/2 -> 9 | E32: ='Lista 1'!B32 -> 1 | F32: ='Lista 2'!B32 -> 1 | G32: =SUM(E32:F32)*5 -> 10 | H32: ='Lista 1'!G32 -> 9.5 | I32: =10 -> 10 | J32: =SUM(H32:I32)/2 -> 9.75 | K32: ='Prova 1'!B32/10 -> 2.6 | L32: =_xlfn.FLOOR.MATH(10*((SUM(D32*0.2,G32*0.05,J32*0.05,K32)*(6/5))*(20/43) + (138/43)))/10 -> 6.2
A33: JOSÉ ARMANDO SILVA DUARTE | B33: ='Teste 1'!B33 -> 10 | C33: ='Teste 2'!B33 -> 9.5 | D33: =SUM(B33:C33)/2 -> 9.75 | E33: ='Lista 1'!B33 -> 1 | F33: ='Lista 2'!B33 -> 1 | G33: =SUM(E33:F33)*5 -> 10 | H33: ='Lista 1'!G33 -> 9.8 | I33: =10 -> 10 | J33: =SUM(H33:I33)/2 -> 9.9 | K33: ='Prova 1'!B33/10 -> 3.4 | L33: =_xlfn.FLOOR.MATH(10*((SUM(D33*0.2,G33*0.05,J33*0.05,K33)*(6/5))*(20/43) + (138/43)))/10 -> 6.7
A34: JOSÉ RAFAEL FREITAS DE MELO | B34: ='Teste 1'!B34 -> 10 | C34: ='Teste 2'!B34 -> 9 | D34: =SUM(B34:C34)/2 -> 9.5 | E34: ='Lista 1'!B34 -> 1 | F34: ='Lista 2'!B34 -> 1 | G34: =SUM(E34:F34)*5 -> 10 | H34: ='Lista 1'!G34 -> 9.5 | I34: =10 -> 10 | J34: =SUM(H34:I34)/2 -> 9.75 | K34: ='Prova 1'!B34/10 -> 3.6 | L34: =_xlfn.FLOOR.MATH(10*((SUM(D34*0.2,G34*0.05,J34*0.05,K34)*(6/5))*(20/43) + (138/43)))/10 -> 6.8
A35: JOSIETE MORAIS SANTOS SILVA | B35: ='Teste 1'!B35 -> 0 | C35: ='Teste 2'!B35 -> 0 | D35: =SUM(B35:C35)/2 -> 0 | E35: ='Lista 1'!B35 -> 0 | F35: ='Lista 2'!B35 -> 0 | G35: =SUM(E35:F35)*5 -> 0 | H35: ='Lista 1'!G35 -> 0 | I35: 0 | J35: =SUM(H35:I35)/2 -> 0 | K35: ='Prova 1'!B35/10 -> 0 | L35: 0
A36: JUAN MARTINS SANTOS | B36: ='Teste 1'!B36 -> 10 | C36: ='Teste 2'!B36 -> 10 | D36: =SUM(B36:C36)/2 -> 10 | E36: ='Lista 1'!B36 -> 1 | F36: ='Lista 2'!B36 -> 0 | G36: =SUM(E36:F36)*5 -> 5 | H36: ='Lista 1'!G36 -> 10 | I36: 0 | J36: =SUM(H36:I36)/2 -> 5 | K36: ='Prova 1'!B36/10 -> 5 | L36: =_xlfn.FLOOR.MATH(10*((SUM(D36*0.2,G36*0.05,J36*0.05,K36)*(6/5))*(20/43) + (138/43)))/10 -> 7.3
A37: JULIA QUIUQUI FONSECA | B37: ='Teste 1'!B37 -> 8 | C37: ='Teste 2'!B37 -> 10 | D37: =SUM(B37:C37)/2 -> 9 | E37: ='Lista 1'!B37 -> 1 | F37: ='Lista 2'!B37 -> 1 | G37: =SUM(E37:F37)*5 -> 10 | H37: ='Lista 1'!G37 -> 10 | I37: =10 -> 10 | J37: =SUM(H37:I37)/2 -> 10 | K37: ='Prova 1'!B37/10 -> 2 | L37: =_xlfn.FLOOR.MATH(10*((SUM(D37*0.2,G37*0.05,J37*0.05,K37)*(6/5))*(20/43) + (138/43)))/10 -> 5.8
A38: KAUÃ MATTES REICHERT | B38: ='Teste 1'!B38 -> 10 | C38: ='Teste 2'!B38 -> 10 | D38: =SUM(B38:C38)/2 -> 10 | E38: ='Lista 1'!B38 -> 1 | F38: ='Lista 2'!B38 -> 1 | G38: =SUM(E38:F38)*5 -> 10 | H38: ='Lista 1'!G38 -> 10 | I38: =10 -> 10 | J38: =SUM(H38:I38)/2 -> 10 | K38: ='Prova 1'!B38/10 -> 8.8 | L38: =_xlfn.FLOOR.MATH(10*((SUM(D38*0.2,G38*0.05,J38*0.05,K38)*(6/5))*(20/43) + (138/43)))/10 -> 9.7
A39: KAYKY LOPES TEIXEIRA MARTINS | B39: ='Teste 1'!B39 -> 10 | C39: ='Teste 2'!B39 -> 10 | D39: =SUM(B39:C39)/2 -> 10 | E39: ='Lista 1'!B39 -> 1 | F39: ='Lista 2'!B39 -> 0 | G39: =SUM(E39:F39)*5 -> 5 | H39: ='Lista 1'!G39 -> 10 | I39: 0 | J39: =SUM(H39:I39)/2 -> 5 | K39: ='Prova 1'!B39/10 -> 2.4 | L39: 6
A40: KENZO NAGAMINE | B40: ='Teste 1'!B40 -> 10 | C40: ='Teste 2'!B40 -> 10 | D40: =SUM(B40:C40)/2 -> 10 | E40: ='Lista 1'!B40 -> 1 | F40: ='Lista 2'!B40 -> 1 | G40: =SUM(E40:F40)*5 -> 10 | H40: ='Lista 1'!G40 -> 10 | I40: =10 -> 10 | J40: =SUM(H40:I40)/2 -> 10 | K40: ='Prova 1'!B40/10 -> 7.6 | L40: =_xlfn.FLOOR.MATH(10*((SUM(D40*0.2,G40*0.05,J40*0.05,K40)*(6/5))*(20/43) + (138/43)))/10 -> 9.1
...

Sheet Teste Extra 1
A1: Nome | B1: Nota
A2: ALAN DAVID SANTOS
A3: ALLAN YUKIO FURUHASHI MELO | B3: 0.1
A4: AMON CHALEGRE GOMES VANDERLEI
A5: ANDRÉ FELIPE FURRIEL OLIVEIRA | B5: 0
A6: ANIZIO SILVA CORREIA JÚNIOR
A7: ARTHUR BARBOSA PINHEIRO | B7: 0.05
A8: CARLOS EDUARDO MACHADO DOS SANTOS | B8: 0
A9: CARLOS EDUARDO ROCHA DE PAULA | B9: 0
A10: CRISTIANE MAGARINOS SAMPAIO | B10: 0.05
A11: DANIEL RODRIGUES SERQUEIRA | B11: 0
A12: DANIELA DE MENEZES MORAES | B12: 0.05
A13: DAVI BEZERRA LEAL GUIMARÃES | B13: 0.05
A14: DAVI PESTANA DE CAMPOS
A15: DULCE MARIA DE ALMEIDA COSTA | B15: 0.05
A16: EMILLY VITÓRIA LEITE REZENDE | B16: 0
A17: FELIPE BECKER FROHLICH | B17: 0
A18: FELIPE LERIA DE OLIVEIRA | B18: 0
A19: FELIPE LIMA DE SOUSA | B19: 0
A20: FELIPE RIBEIRO MENDONÇA | B20: 0
A21: GABRIEL COLATUSSO CASTRO DA CRUZ | B21: 0
A22: GABRIEL FALCÃO MARTINEZ | B22: 0
A23: GABRIEL KRAUSS DE SANTANA DIAS | B23: 0.1
A24: GABRIELA NAOMI ICHICAWA OGIDO | B24: 0.05
A25: GUILHERME OSÉIAS PEREIRA DA SILVA | B25: 0
A26: GUILHERME WILLEMEN PIMENTEL DE CASTRO
A27: HEITOR ALVES BRAZUNA | B27: 0.1
A28: HEITOR RAMOS PEREIRA | B28: 0.05
A29: Huann Vicente | B29: 0
A30: INGRID SILVA CARVALHO | B30: 0.05
A31: ITALO RENNAN DE ABREU SOUZA | B31: 0
A32: JONAS ARAUJO ALVES | B32: 0
A33: JOSÉ ARMANDO SILVA DUARTE | B33: 0.08
A34: JOSÉ RAFAEL FREITAS DE MELO | B34: 0
A35: JOSIETE MORAIS SANTOS SILVA
A36: JUAN MARTINS SANTOS | B36: 0
A37: JULIA QUIUQUI FONSECA | B37: 0.05
A38: KAUÃ MATTES REICHERT | B38: 0.1
A39: KAYKY LOPES TEIXEIRA MARTINS | B39: 0
A40: KENZO NAGAMINE | B40: 0.1
...

Sheet Teste Extra 2
A1: Nome | B1: Nota
A2: ALAN DAVID SANTOS
A3: ALLAN YUKIO FURUHASHI MELO | B3: 0.03
A4: AMON CHALEGRE GOMES VANDERLEI
A5: ANDRÉ FELIPE FURRIEL OLIVEIRA | B5: 0
A6: ANIZIO SILVA CORREIA JÚNIOR | B6: 0.1
A7: ARTHUR BARBOSA PINHEIRO | B7: 0.1
A8: CARLOS EDUARDO MACHADO DOS SANTOS | B8: 0
A9: CARLOS EDUARDO ROCHA DE PAULA | B9: 0
A10: CRISTIANE MAGARINOS SAMPAIO | B10: 0.03
A11: DANIEL RODRIGUES SERQUEIRA | B11: 0
A12: DANIELA DE MENEZES MORAES | B12: 0
A13: DAVI BEZERRA LEAL GUIMARÃES | B13: 0
A14: DAVI PESTANA DE CAMPOS
A15: DULCE MARIA DE ALMEIDA COSTA | B15: 0.03
A16: EMILLY VITÓRIA LEITE REZENDE | B16: 0
A17: FELIPE BECKER FROHLICH | B17: 0.1
A18: FELIPE LERIA DE OLIVEIRA | B18: 0.1
A19: FELIPE LIMA DE SOUSA | B19: 0
A20: FELIPE RIBEIRO MENDONÇA | B20: 0.02
A21: GABRIEL COLATUSSO CASTRO DA CRUZ | B21: 0.07
A22: GABRIEL FALCÃO MARTINEZ | B22: 0.1
A23: GABRIEL KRAUSS DE SANTANA DIAS | B23: 0
A24: GABRIELA NAOMI ICHICAWA OGIDO | B24: 0.01
A25: GUILHERME OSÉIAS PEREIRA DA SILVA | B25: 0
A26: GUILHERME WILLEMEN PIMENTEL DE CASTRO
A27: HEITOR ALVES BRAZUNA | B27: 0.12
A28: HEITOR RAMOS PEREIRA | B28: 0.04
A29: Huann Vicente | B29: 0
A30: INGRID SILVA CARVALHO | B30: 0
A31: ITALO RENNAN DE ABREU SOUZA | B31: 0.1
A32: JONAS ARAUJO ALVES | B32: 0
A33: JOSÉ ARMANDO SILVA DUARTE | B33: 0
A34: JOSÉ RAFAEL FREITAS DE MELO | B34: 0
A35: JOSIETE MORAIS SANTOS SILVA
A36: JUAN MARTINS SANTOS | B36: 0
A37: JULIA QUIUQUI FONSECA | B37: 0.11
A38: KAUÃ MATTES REICHERT | B38: 0.1
A39: KAYKY LOPES TEIXEIRA MARTINS | B39: 0.02
A40: KENZO NAGAMINE | B40: 0.08
...
